<?xml version="1.0" ?>
<robot name="URDF">

<material name="silver">
  <color rgba="0.700 0.700 0.700 1.000"/>
</material>

<link name="base_link">
  <inertial>
    <origin xyz="4.134574372160573e-14 -1.9697829309959846e-17 -0.0025" rpy="0 0 0"/>
    <mass value="0.9061320027414785"/>
    <inertia ixx="0.0011148442513439273" iyy="0.003073148326209344" izz="0.004184217027541849" ixy="7.139533408910106e-19" iyz="-4.462208380573429e-20" ixz="-1.232595164407831e-32"/>
  </inertial>
  <visual>
    <origin xyz="0 0 0" rpy="0 0 0"/>
    <geometry>
      <mesh filename="meshes/base_link.stl" scale="0.001 0.001 0.001"/>
    </geometry>
    <material name="silver"/>
    <material/>
  </visual>
  <collision>
    <origin xyz="0 0 0" rpy="0 0 0"/>
    <geometry>
      <mesh filename="meshes/base_link.stl" scale="0.001 0.001 0.001"/>
    </geometry>
  </collision>
</link>

<link name="hand_v111">
  <inertial>
    <origin xyz="0.013399974863583353 0.0014673587274294318 -0.10494199895736095" rpy="0 0 0"/>
    <mass value="1.5734552063055838"/>
    <inertia ixx="0.005827888610414889" iyy="0.004512634007797889" izz="0.0018811830424321774" ixy="1.684683106096879e-05" iyz="0.00015213115592073293" ixz="0.0005095337397744704"/>
  </inertial>
  <visual>
    <origin xyz="0.560233 -0.001221 -0.509635" rpy="0 0 0"/>
    <geometry>
      <mesh filename="meshes/hand_v111.stl" scale="0.001 0.001 0.001"/>
    </geometry>
    <material name="silver"/>
    <material/>
  </visual>
  <collision>
    <origin xyz="0.560233 -0.001221 -0.509635" rpy="0 0 0"/>
    <geometry>
      <mesh filename="meshes/hand_v111.stl" scale="0.001 0.001 0.001"/>
    </geometry>
  </collision>
</link>

<link name="J5to6_v111">
  <inertial>
    <origin xyz="0.0014998156879051372 4.651259435907982e-05 -0.012405591131645632" rpy="0 0 0"/>
    <mass value="0.35001351454511986"/>
    <inertia ixx="0.00015735906684131995" iyy="0.00012056272744911944" izz="0.00011199297706979139" ixy="4.551893305118344e-07" iyz="-9.40434411947225e-09" ixz="6.291595880350553e-06"/>
  </inertial>
  <visual>
    <origin xyz="0.564546 -0.001126 -0.54336" rpy="0 0 0"/>
    <geometry>
      <mesh filename="meshes/J5to6_v111.stl" scale="0.001 0.001 0.001"/>
    </geometry>
    <material name="silver"/>
    <material/>
  </visual>
  <collision>
    <origin xyz="0.564546 -0.001126 -0.54336" rpy="0 0 0"/>
    <geometry>
      <mesh filename="meshes/J5to6_v111.stl" scale="0.001 0.001 0.001"/>
    </geometry>
  </collision>
</link>

<link name="J4to5_v111">
  <inertial>
    <origin xyz="6.804744117183681e-06 0.0005227247602343128 -0.029392065957235425" rpy="0 0 0"/>
    <mass value="4.55070610869959"/>
    <inertia ixx="0.006605063772559205" iyy="0.007372513516280765" izz="0.006030026661363097" ixy="-0.00014257460668079362" iyz="0.0001476778562341241" ixz="-6.699233237927871e-06"/>
  </inertial>
  <visual>
    <origin xyz="0.563444 -0.00115 -0.6375" rpy="0 0 0"/>
    <geometry>
      <mesh filename="meshes/J4to5_v111.stl" scale="0.001 0.001 0.001"/>
    </geometry>
    <material name="silver"/>
    <material/>
  </visual>
  <collision>
    <origin xyz="0.563444 -0.00115 -0.6375" rpy="0 0 0"/>
    <geometry>
      <mesh filename="meshes/J4to5_v111.stl" scale="0.001 0.001 0.001"/>
    </geometry>
  </collision>
</link>

<link name="J3to4_v111">
  <inertial>
    <origin xyz="-0.4157580723258036 -1.528505906127852e-05 0.006491989161569012" rpy="0 0 0"/>
    <mass value="5.095305748645674"/>
    <inertia ixx="0.00498273335346866" iyy="0.21542063384156096" izz="0.2152159667442668" ixy="-1.1784222023251273e-05" iyz="2.0063157415307203e-06" ixz="0.004784669024316512"/>
  </inertial>
  <visual>
    <origin xyz="0.001 -0.00115 -0.655" rpy="0 0 0"/>
    <geometry>
      <mesh filename="meshes/J3to4_v111.stl" scale="0.001 0.001 0.001"/>
    </geometry>
    <material name="silver"/>
    <material/>
  </visual>
  <collision>
    <origin xyz="0.001 -0.00115 -0.655" rpy="0 0 0"/>
    <geometry>
      <mesh filename="meshes/J3to4_v111.stl" scale="0.001 0.001 0.001"/>
    </geometry>
  </collision>
</link>

<link name="J2to3_v211">
  <inertial>
    <origin xyz="0.0002441964978063141 -0.012514943272552637 0.42977520138921277" rpy="0 0 0"/>
    <mass value="6.769699046992388"/>
    <inertia ixx="0.2338505574541987" iyy="0.23194401766464656" izz="0.011828487592585814" ixy="-1.5074859269826562e-05" iyz="0.0072162921549105835" ixz="0.0002321578378231665"/>
  </inertial>
  <visual>
    <origin xyz="0.001 -0.00115 -0.117" rpy="0 0 0"/>
    <geometry>
      <mesh filename="meshes/J2to3_v211.stl" scale="0.001 0.001 0.001"/>
    </geometry>
    <material name="silver"/>
    <material/>
  </visual>
  <collision>
    <origin xyz="0.001 -0.00115 -0.117" rpy="0 0 0"/>
    <geometry>
      <mesh filename="meshes/J2to3_v211.stl" scale="0.001 0.001 0.001"/>
    </geometry>
  </collision>
</link>

<link name="J1to2_v111">
  <inertial>
    <origin xyz="-0.0009792145863911212 0.0003228728553376847 0.05805748683050891" rpy="0 0 0"/>
    <mass value="8.776151756630489"/>
    <inertia ixx="0.027743709580449256" iyy="0.0346202144137127" izz="0.02105806526379412" ixy="-1.8975944281594924e-05" iyz="-0.0001396115762032384" ixz="0.000155329111539089"/>
  </inertial>
  <visual>
    <origin xyz="-0.0 -0.0 -0.0" rpy="0 0 0"/>
    <geometry>
      <mesh filename="meshes/J1to2_v111.stl" scale="0.001 0.001 0.001"/>
    </geometry>
    <material name="silver"/>
    <material/>
  </visual>
  <collision>
    <origin xyz="-0.0 -0.0 -0.0" rpy="0 0 0"/>
    <geometry>
      <mesh filename="meshes/J1to2_v111.stl" scale="0.001 0.001 0.001"/>
    </geometry>
  </collision>
</link>

<joint name="Revolute_1" type="continuous">
  <origin xyz="0.004313 9.5e-05 -0.033725" rpy="0 0 0"/>
  <parent link="J5to6_v111"/>
  <child link="hand_v111"/>
  <axis xyz="0.126869 0.002806 -0.991916"/>
</joint>
<transmission name="Revolute_1_tran">
  <type>transmission_interface/SimpleTransmission</type>
  <joint name="Revolute_1">
    <hardwareInterface>PositionJointInterface</hardwareInterface>
  </joint>
  <actuator name="Revolute_1_actr">
    <hardwareInterface>PositionJointInterface</hardwareInterface>
    <mechanicalReduction>1</mechanicalReduction>
  </actuator>
</transmission>

<joint name="Revolute_2" type="continuous">
  <origin xyz="-0.001102 -2.4e-05 -0.09414" rpy="0 0 0"/>
  <parent link="J4to5_v111"/>
  <child link="J5to6_v111"/>
  <axis xyz="0.022114 -0.999755 0.0"/>
</joint>
<transmission name="Revolute_2_tran">
  <type>transmission_interface/SimpleTransmission</type>
  <joint name="Revolute_2">
    <hardwareInterface>PositionJointInterface</hardwareInterface>
  </joint>
  <actuator name="Revolute_2_actr">
    <hardwareInterface>PositionJointInterface</hardwareInterface>
    <mechanicalReduction>1</mechanicalReduction>
  </actuator>
</transmission>

<joint name="Revolute_3" type="continuous">
  <origin xyz="0.562444 0.0 -0.0175" rpy="0 0 0"/>
  <parent link="J3to4_v111"/>
  <child link="J4to5_v111"/>
  <axis xyz="0.0 0.0 1.0"/>
</joint>
<transmission name="Revolute_3_tran">
  <type>transmission_interface/SimpleTransmission</type>
  <joint name="Revolute_3">
    <hardwareInterface>PositionJointInterface</hardwareInterface>
  </joint>
  <actuator name="Revolute_3_actr">
    <hardwareInterface>PositionJointInterface</hardwareInterface>
    <mechanicalReduction>1</mechanicalReduction>
  </actuator>
</transmission>

<joint name="Revolute_4" type="continuous">
  <origin xyz="0.0 0.0 0.538" rpy="0 0 0"/>
  <parent link="J2to3_v211"/>
  <child link="J3to4_v111"/>
  <axis xyz="0.0 1.0 -0.0"/>
</joint>
<transmission name="Revolute_4_tran">
  <type>transmission_interface/SimpleTransmission</type>
  <joint name="Revolute_4">
    <hardwareInterface>PositionJointInterface</hardwareInterface>
  </joint>
  <actuator name="Revolute_4_actr">
    <hardwareInterface>PositionJointInterface</hardwareInterface>
    <mechanicalReduction>1</mechanicalReduction>
  </actuator>
</transmission>

<joint name="Revolute_5" type="continuous">
  <origin xyz="-0.001 0.00115 0.117" rpy="0 0 0"/>
  <parent link="J1to2_v111"/>
  <child link="J2to3_v211"/>
  <axis xyz="-0.0 1.0 -0.0"/>
</joint>
<transmission name="Revolute_5_tran">
  <type>transmission_interface/SimpleTransmission</type>
  <joint name="Revolute_5">
    <hardwareInterface>PositionJointInterface</hardwareInterface>
  </joint>
  <actuator name="Revolute_5_actr">
    <hardwareInterface>PositionJointInterface</hardwareInterface>
    <mechanicalReduction>1</mechanicalReduction>
  </actuator>
</transmission>

<joint name="Revolute_6" type="continuous">
  <origin xyz="0.0 0.0 0.0" rpy="0 0 0"/>
  <parent link="base_link"/>
  <child link="J1to2_v111"/>
  <axis xyz="0.0 0.0 1.0"/>
</joint>
<transmission name="Revolute_6_tran">
  <type>transmission_interface/SimpleTransmission</type>
  <joint name="Revolute_6">
    <hardwareInterface>PositionJointInterface</hardwareInterface>
  </joint>
  <actuator name="Revolute_6_actr">
    <hardwareInterface>PositionJointInterface</hardwareInterface>
    <mechanicalReduction>1</mechanicalReduction>
  </actuator>
</transmission>

</robot>
